Workbook

Sheet AD
A1: id | B1: age | C1: sex | D1: spb | E1: dbp | F1: HR (bpm) | G1: pwv lt_ica | H1: pwv rt_ica | I1: pwv_avg | J1: flow petrous L&R | K1: PI petrous L&R | L1: apoe_e1 | M1: apoe_e2 | N1: FmHx_dementia
A2: 'adrc00343_v2' | B2: 87.97 | C2: Male | D2: 146 | E2: 80 | F2: 63.5593 | G2: 22.7851 | H2: 24.1701 | I2: 23.4776 | J2: 3.29 | K2: 1.385 | L2: 3 | M2: 3 | N2: 0
A3: 'adrc00405_v2' | B3: 72.51 | C3: Female | D3: 150 | E3: 80 | F3: 92.8793 | G3: 42.6706 | H3: 61.8207 | I3: 52.24565 | J3: 2.455 | K3: 1.335 | L3: 3 | M3: 4 | N3: 1
A4: 'adrc00564' | B4: 69.89 | C4: Male | D4: 143 | E4: 78 | F4: 60.3622 | G4: 42.9005 | H4: 10.4241 | I4: 26.6623 | J4: 3.205 | K4: 1.27 | L4: 2 | M4: 3 | N4: 0
A5: 'adrc00609_v2' | B5: 73.79 | C5: Female | D5: 135 | E5: 74 | F5: 58.1395 | G5: 21.2414 | H5: 14.2388 | I5: 17.7401 | J5: 3.395 | K5: 1.435 | L5: 3 | M5: 4 | N5: 0
A6: 'adrc00739' | B6: 69.59 | C6: Male | D6: 115 | E6: 74 | F6: 55.2486 | G6: 23.5081 | H6: 12.072 | I6: 17.79005 | J6: 2.4 | K6: 1.25 | L6: 3 | M6: 4 | N6: 0
A7: 'adrc00750' | B7: 69.97 | C7: Female | D7: 131 | E7: 81 | F7: 56.4972 | G7: 24.6867 | H7: 28.1528 | I7: 26.41975 | J7: 3.085 | K7: 1.175 | L7: 4 | M7: 4 | N7: 1
A8: 'adrc00778' | B8: 71.55 | C8: Female | D8: 116 | E8: 74 | F8: 56.7108 | G8: 31.1677 | H8: 40.2925 | I8: 35.7301 | J8: 2.85 | K8: 1.415 | L8: 3 | M8: 4 | N8: 1
A9: 'adrc00791' | B9: 83.97 | C9: Female | D9: 158 | E9: 71 | F9: 66.0793 | G9: 33.9961 | H9: 14.5291 | I9: 24.2626 | J9: 4.43 | K9: 1.815 | N9: 1
A10: 'adrc00811' | B10: 60.7 | C10: Female | D10: 106 | E10: 69 | F10: 46.0829 | G10: 20.7964 | H10: 20.4119 | I10: 20.60415 | J10: 3.615 | K10: 0.935 | L10: 3 | M10: 3 | N10: 0
A11: 'adrc00820' | B11: 75.32 | C11: Female | D11: 148 | E11: 76 | F11: 71.2589 | H11: 25.7992 | I11: 25.7992 | J11: 3.13 | K11: 1.01 | L11: 3 | M11: 4 | N11: 1
A12: 'adrc00860' | B12: 79.81 | C12: Male | D12: 163 | E12: 75 | F12: 58.8235 | G12: 47.8929 | H12: 27.5652 | I12: 37.72905 | J12: 3.08 | K12: 1.54 | L12: 3 | M12: 3 | N12: 0
A13: 'adrc00863' | B13: 78.37 | C13: Female | D13: 125 | E13: 84 | F13: 58.9391 | G13: 40.6728 | H13: 18.9284 | I13: 29.8006 | J13: 2.49 | K13: 1.28 | N13: 0
A14: 'adrc00893' | B14: 66.95 | C14: Male | D14: 132 | E14: 81 | F14: 61.6016 | G14: 53.2659 | H14: 39.7415 | I14: 46.5037 | J14: 2.11 | K14: 1.43 | L14: 3 | M14: 3 | N14: 1
A15: 'adrc00894' | B15: 68.4 | C15: Female | D15: 128 | E15: 83 | F15: 44.7094 | G15: 22.1171 | H15: 13.7371 | I15: 17.9271 | J15: 4.425 | K15: 0.915 | N15: 0
A16: 'adrc00903' | B16: 87.92 | C16: Female | D16: 110 | E16: 68 | F16: 78.7402 | G16: 15.723 | H16: 21.2495 | I16: 18.48625 | J16: 2.67 | K16: 1.51 | L16: 2 | M16: 3 | N16: 0
A17: 'adrc00919' | B17: 77.85 | C17: Male | D17: 134 | E17: 79 | F17: 55.0459 | G17: 33.9934 | H17: 40.3648 | I17: 37.1791 | J17: 2.81 | K17: 1.185 | N17: 0
A18: 'adrc00920' | B18: 56.52 | C18: Female | D18: 110 | E18: 68 | F18: 55.2486 | G18: 17.0583 | H18: 40.9106 | I18: 28.98445 | J18: 5.2 | K18: 0.68 | N18: 0
A19: 'adrc00934' | B19: 67.95 | C19: Female | D19: 117 | E19: 71 | F19: 53.9568 | G19: 27.2989 | H19: 33.9629 | I19: 30.6309 | J19: 3.965 | K19: 1.065 | N19: 1
A20: 'adrc00939' | B20: 88.55 | C20: Female | D20: 153 | E20: 72 | F20: 55.9701 | G20: 17.7166 | H20: 29.0608 | I20: 23.3887 | J20: 2.285 | K20: 1.955 | N20: 0
A21: 'adrc00964' | B21: 60.63 | C21: Male | D21: 95 | E21: 61 | F21: 50 | G21: 18.1421 | H21: 16.5245 | I21: 17.3333 | J21: 2.89 | K21: 1.26 | N21: 0
A23: ="# SUBJECTS= " & COUNTA(A2:A21) -> # SUBJECTS= 20 | C23: Female/Male
A24: Mean | B24: =AVERAGE(B2:B21) -> 73.4105 | C24: =COUNTIF(C2:C21,"Female") -> 13 | D24: =AVERAGE(D2:D21) -> 130.75 | E24: =AVERAGE(E2:E21) -> 74.95 | F24: =AVERAGE(F2:F21) -> 59.99266 | G24: =AVERAGE(G2:G21) -> 29.349137 | H24: =AVERAGE(H2:H21) -> 26.697825 | I24: =AVERAGE(I2:I21) -> 27.934732 | J24: =AVERAGE(J2:J21) -> 3.189 | K24: =AVERAGE(K2:K21) -> 1.29225 | N24: =COUNTIF(N2:N21,0) -> 13
A25: Std Dev | B25: =_xlfn.STDEV.S(B2:B21) -> 9.1829605 | C25: =COUNTIF(C2:C21,"Male") -> 7 | D25: =_xlfn.STDEV.S(D2:D21) -> 18.926103 | E25: =_xlfn.STDEV.S(E2:E21) -> 5.9247474 | F25: =_xlfn.STDEV.S(F2:F21) -> 10.979241 | G25: =_xlfn.STDEV.S(G2:G21) -> 11.410674 | H25: =_xlfn.STDEV.S(H2:H21) -> 13.036147 | I25: =_xlfn.STDEV.S(I2:I21) -> 9.7730184 | J25: =_xlfn.STDEV.S(J2:J21) -> 0.80207888 | K25: =_xlfn.STDEV.S(K2:K21) -> 0.29832636 | N25: =COUNTIF(N2:N21,1) -> 7
A26: Maximum | B26: =MAX(B2:B21) -> 88.55 | C26: =SUM(C24:C25) -> 20 | D26: =MAX(D2:D21) -> 163 | E26: =MAX(E2:E21) -> 84 | F26: =MAX(F2:F21) -> 92.8793 | G26: =MAX(G2:G21) -> 53.2659 | H26: =MAX(H2:H21) -> 61.8207 | I26: =MAX(I2:I21) -> 52.24565 | J26: =MAX(J2:J21) -> 5.2 | K26: =MAX(K2:K21) -> 1.955 | N26: =SUM(N24:N25) -> 20
A27: Minimum | B27: =MIN(B2:B21) -> 56.52 | C27: =C24/(C24+C25)*100 -> 65 | D27: =MIN(D2:D21) -> 95 | E27: =MIN(E2:E21) -> 61 | F27: =MIN(F2:F21) -> 44.7094 | G27: =MIN(G2:G21) -> 15.723 | H27: =MIN(H2:H21) -> 10.4241 | I27: =MIN(I2:I21) -> 17.3333 | J27: =MIN(J2:J21) -> 2.11 | K27: =MIN(K2:K21) -> 0.68 | N27: =N25/N26*100 -> 35
A29: Categorical | K29: APOE e2,2 | L29: 0
K30: APOE e2,3/3,2 | L30: 2
K31: APOE e3,3 | L31: 4
K32: APOE e3,4/4,3 | L32: 5
K33: APOE e4,4 | L33: 1
K34: Unknown | L34: 8

Sheet MCI
A1: id | B1: age | C1: sex | D1: spb | E1: dbp | F1: HR (bpm) | G1: pwv lt_ica | H1: pwv rt_ica | I1: pwv_avg | J1: flow petrous L&R | K1: PI petrous L&R | L1: apoe_e1 | M1: apoe_e2 | N1: FmHx_dementia
A2: 'adrc00302_v2' | B2: 62.76 | C2: Male | D2: 121 | E2: 74 | F2: 55.4529 | G2: 27.5819 | H2: 27.6869 | I2: 27.6344 | J2: 3.74 | K2: 1.12 | L2: 3 | M2: 4 | N2: 0
A3: 'adrc00383' | B3: 59.66 | C3: Female | D3: 130 | E3: 89 | F3: 71.4286 | G3: 17.145 | H3: 20.7848 | I3: 18.9649 | J3: 4.1 | K3: 1 | L3: 3 | M3: 3 | N3: 0
A4: 'adrc00404' | B4: 54.12 | C4: Male | D4: 143 | E4: 88 | F4: 56.391 | G4: 28.2271 | H4: 20.3674 | I4: 24.29725 | J4: 4.435 | K4: 1.155 | L4: 3 | M4: 3 | N4: 1
A5: 'adrc00457_v2' | B5: 67.52 | C5: Female | D5: 147 | E5: 81 | F5: 39.6825 | G5: 16.2661 | H5: 24.9789 | I5: 20.6225 | J5: 3.78 | K5: 1.21 | L5: 3 | M5: 3 | N5: 0
A6: 'adrc00667_v2' | B6: 78.06 | C6: Male | D6: 126 | E6: 81 | F6: 59.0551 | G6: 5.3332 | H6: 31.0604 | I6: 18.1968 | J6: 2.735 | K6: 1.25 | L6: 3 | M6: 4 | N6: 0
A7: 'adrc00695_v2' | B7: 84.33 | C7: Female | F7: 62.8931 | G7: 19.2541 | H7: 4.8138 | I7: 12.03395 | J7: 2.77 | K7: 1.07 | L7: 3 | M7: 3 | N7: 1
A8: 'adrc00713_v2' | B8: 49.85 | C8: Male | D8: 127 | E8: 83 | F8: 63.5593 | G8: 19.8875 | H8: 32.1699 | I8: 26.0287 | J8: 4.01 | K8: 0.935 | L8: 2 | M8: 3 | N8: 1
A9: 'adrc00715' | B9: 65.62 | C9: Male | D9: 145 | E9: 86 | F9: 64.1026 | G9: 13.8732 | H9: 6.3986 | I9: 10.1359 | J9: 3.185 | K9: 1.02 | L9: 3 | M9: 4 | N9: 1
A10: 'adrc00730_v2' | B10: 87.16 | C10: Male | D10: 99 | E10: 62 | F10: 62.7615 | G10: 29.9409 | H10: 24.8754 | I10: 27.40815 | J10: 3.64 | K10: 1.3025 | L10: 2 | M10: 3 | N10: 1
A11: 'adrc00734' | B11: 67.64 | C11: Female | D11: 136 | E11: 83 | F11: 69.9301 | G11: 41.4415 | H11: 10.4872 | I11: 25.96435 | J11: 3.205 | K11: 0.9 | L11: 3 | M11: 3 | N11: 0
A12: 'adrc00765' | B12: 77.31 | C12: Female | D12: 152 | E12: 78 | F12: 84.2697 | G12: 13.9336 | H12: 24.6045 | I12: 19.26905 | J12: 4.215 | K12: 1.05 | L12: 3 | M12: 4 | N12: 0
A13: 'adrc00780_v2' | B13: 62.94 | C13: Female | D13: 125 | E13: 79 | F13: 62.3701 | G13: 17.1401 | H13: 18.2591 | I13: 17.6996 | J13: 2.94 | K13: 1.18 | L13: 3 | M13: 3 | N13: 0
A14: 'adrc00783' | B14: 85.92 | C14: Male | D14: 166 | E14: 72 | F14: 55.1471 | G14: 39.103 | H14: 18.5565 | I14: 28.82975 | J14: 4.02 | K14: 1.435 | L14: 3 | M14: 3 | N14: 0
A15: 'adrc00807' | B15: 78.34 | C15: Female | D15: 129 | E15: 73 | F15: 50.1672 | H15: 26.6475 | I15: 26.6475 | J15: 3.24 | K15: 1.24 | L15: 2 | M15: 3 | N15: 0
A16: 'adrc00892' | B16: 81.68 | C16: Female | D16: 144 | E16: 77 | F16: 66.2252 | G16: 20.2065 | H16: 30.6575 | I16: 25.432 | J16: 3.02 | K16: 1.36 | N16: 1
A17: 'adrc00897' | B17: 81.8 | C17: Female | D17: 132 | E17: 71 | F17: 66.2252 | G17: 52.9334 | H17: 27.7064 | I17: 40.3199 | J17: 3.04 | K17: 1.57 | N17: 1
A18: 'adrc00929' | B18: 74.82 | C18: Male | D18: 119 | E18: 75 | F18: 48 | G18: 19.4512 | H18: 18.8837 | I18: 19.16745 | J18: 3.98 | K18: 1.14 | N18: 0
A19: 'adrc00933' | B19: 66.64 | C19: Female | D19: 124 | E19: 76 | F19: 51.7241 | G19: 31.4643 | H19: 27.0182 | I19: 29.24125 | J19: 3.57 | K19: 1.14 | N19: 0
A20: 'adrc00937' | B20: 75.66 | C20: Male | D20: 128 | E20: 79 | F20: 43.9239 | G20: 24.2201 | H20: 24.4256 | I20: 24.32285 | J20: 3.09 | K20: 1.285 | N20: 1
A21: 'adrc00946' | B21: 70.33 | C21: Male | D21: 160 | E21: 90 | F21: 49.505 | G21: 20.2323 | H21: 43.6268 | I21: 31.92955 | J21: 4.075 | K21: 1.375 | N21: 0
A23: ="# SUBJECTS= " & COUNTA(A2:A21) -> # SUBJECTS= 20 | C23: Female
A24: Mean | B24: =AVERAGE(B2:B21) -> 71.608 | C24: =COUNTIF(C2:C21,"Female") -> 10 | D24: =AVERAGE(D2:D21) -> 134.36842 | E24: =AVERAGE(E2:E21) -> 78.789474 | F24: =AVERAGE(F2:F21) -> 59.14071 | G24: =AVERAGE(G2:G21) -> 24.086053 | H24: =AVERAGE(H2:H21) -> 23.200455 | I24: =AVERAGE(I2:I21) -> 23.70729 | J24: =AVERAGE(J2:J21) -> 3.5395 | K24: =AVERAGE(K2:K21) -> 1.186875
A25: Std Dev | B25: =_xlfn.STDEV.S(B2:B21) -> 10.58825 | D25: =_xlfn.STDEV.S(D2:D21) -> 15.794551 | E25: =_xlfn.STDEV.S(E2:E21) -> 7.0045933 | F25: =_xlfn.STDEV.S(F2:F21) -> 10.464969 | G25: =_xlfn.STDEV.S(G2:G21) -> 11.269365 | H25: =_xlfn.STDEV.S(H2:H21) -> 9.0375822 | I25: =_xlfn.STDEV.S(I2:I21) -> 6.9267543 | J25: =_xlfn.STDEV.S(J2:J21) -> 0.52625514 | K25: =_xlfn.STDEV.S(K2:K21) -> 0.17089331
A26: Maximum | B26: =MAX(B2:B21) -> 87.16 | D26: =MAX(D2:D21) -> 166 | E26: =MAX(E2:E21) -> 90 | F26: =MAX(F2:F21) -> 84.2697 | G26: =MAX(G2:G21) -> 52.9334 | H26: =MAX(H2:H21) -> 43.6268 | I26: =MAX(I2:I21) -> 40.3199 | J26: =MAX(J2:J21) -> 4.435 | K26: =MAX(K2:K21) -> 1.57
A27: Minimum | B27: =MIN(B2:B21) -> 49.85 | D27: =MIN(D2:D21) -> 99 | E27: =MIN(E2:E21) -> 62 | F27: =MIN(F2:F21) -> 39.6825 | G27: =MIN(G2:G21) -> 5.3332 | H27: =MIN(H2:H21) -> 4.8138 | I27: =MIN(I2:I21) -> 10.1359 | J27: =MIN(J2:J21) -> 2.735 | K27: =MIN(K2:K21) -> 0.9

Sheet CN
A1: id | B1: age | C1: sex | D1: spb | E1: dbp | F1: HR (bpm) | G1: pwv lt_ica | H1: pwv rt_ica | I1: pwv_avg | J1: flow petrous L&R | K1: PI petrous L&R | L1: apoe_e1 | M1: apoe_e2 | N1: FmHx_dementia
A2: 'pdt00258_v3' | B2: 69.3 | C2: Female | D2: 107 | E2: 67 | F2: 60 | G2: 3.4546 | H2: 38.3758 | I2: 20.9152 | J2: 3.935 | K2: 1.025 | L2: 3 | M2: 3 | N2: 0
A3: 'pdt00218_v3' | B3: 70.35 | C3: Female | D3: 140 | E3: 80 | F3: 58.9391 | G3: 10.974 | H3: 7.8829 | I3: 9.42845 | J3: 3.145 | K3: 1.385 | L3: 3 | M3: 3 | N3: 0
A4: 'pdt00202_v3' | B4: 66.91 | C4: Male | D4: 142 | E4: 87 | F4: 74.4417 | G4: 15.6376 | H4: 3.7263 | I4: 9.68195 | J4: 3.9 | K4: 1.22 | L4: 3 | M4: 3 | N4: 0
A5: 'pdt00092_v3' | B5: 71.31 | C5: Male | D5: 162 | E5: 74 | F5: 54.5455 | G5: 36.79 | H5: 17.3074 | I5: 27.0487 | J5: 2.215 | K5: 1.64 | L5: 3 | M5: 3 | N5: 0
A6: 'pdt00056_v3' | B6: 77.41 | C6: Female | D6: 136 | E6: 82 | F6: 67.2646 | G6: 6.0812 | H6: 17.605 | I6: 11.8431 | J6: 3.345 | K6: 1.23 | L6: 3 | M6: 3 | N6: 0
A7: 'pdt00049_v3' | B7: 73.74 | C7: Male | D7: 134 | E7: 74 | F7: 55.2486 | G7: 4.5718 | H7: 11.3051 | I7: 7.93845 | J7: 3.96 | K7: 1.385 | L7: 3 | M7: 3 | N7: 0
A8: 'pdt00045_v3' | B8: 69.86 | C8: Female | D8: 110 | E8: 68 | F8: 52.1739 | G8: 9.9058 | H8: 9.5239 | I8: 9.71485 | J8: 3.72 | K8: 1.56 | L8: 3 | M8: 3 | N8: 0
A9: 'pdt00035_v3' | B9: 70.31 | C9: Male | D9: 136 | E9: 80 | F9: 64.7948 | G9: 7.2277 | H9: 12.5649 | I9: 9.8963 | J9: 3.87 | K9: 1.145 | L9: 3 | M9: 3 | N9: 0
A10: 'pdt00034_v3' | B10: 73.48 | C10: Female | D10: 156 | E10: 74 | F10: 52.6316 | G10: 19.6663 | H10: 9.2447 | I10: 14.4555 | J10: 3.38 | K10: 1.33 | L10: 3 | M10: 3 | N10: 0
A11: 'adrc00808_v2' | B11: 65.68 | C11: Female | D11: 121 | E11: 74 | F11: 55.4529 | G11: 15.3962 | H11: 7.3219 | I11: 11.35905 | J11: 3.97 | K11: 1.175 | L11: 3 | M11: 4 | N11: 0
A12: 'adrc00788' | B12: 66.59 | C12: Female | D12: 142 | E12: 85 | F12: 71.9424 | G12: 13.7517 | H12: 12.2956 | I12: 13.02365 | J12: 3.77 | K12: 0.925 | L12: 3 | M12: 3 | N12: 1
A13: 'adrc00773' | B13: 68.97 | C13: Male | D13: 113 | E13: 79 | F13: 76.7263 | G13: 6.3975 | H13: 11.9538 | I13: 9.17565 | J13: 3.74 | K13: 0.845 | L13: 2 | M13: 3 | N13: 0
... A40: 'adrc00694_v3' | B40: 69.39 | C40: Female | D40: 113 | E40: 76 | F40: 63.1579 | G40: 3.3709 | H40: 7.8114 | I40: 5.59115 | J40: 3.55 | K40: 0.87 | L40: 3 | M40: 3 | N40: 0
A41: 'adrc00767_v2' | B41: 68.16 | C41: Female | D41: 154 | E41: 90 | F41: 63.9659 | G41: 7.9788 | H41: 8.0018 | I41: 7.9903 | J41: 3.295 | L41: 3 | M41: 3 | N41: 0
A42: 'adrc00855_v2' | B42: 77.94 | C42: Female | D42: 169 | E42: 77 | F42: 63.4249 | G42: 31.0069 | H42: 24.3593 | I42: 27.6831 | J42: 3.305 | K42: 1.53 | L42: 2 | M42: 3 | N42: 0
A44: ="# SUBJECTS= " & COUNTA(A2:A42) -> # SUBJECTS= 41 | C44: Female/Male
A45: Mean/Count+ | B45: =AVERAGE(B2:B42) -> 73.529512 | C45: =COUNTIF(C2:C42,"Female") -> 23 | D45: =AVERAGE(D2:D42) -> 132.39024 | E45: =AVERAGE(E2:E42) -> 77.634146 | F45: =AVERAGE(F2:F42) -> 61.584546 | G45: =AVERAGE(G2:G42) -> 20.732927 | H45: =AVERAGE(H2:H42) -> 14.339607 | I45: =AVERAGE(I2:I42) -> 17.536267 | J45: =AVERAGE(J2:J42) -> 3.4573171 | K45: =AVERAGE(K2:K42) -> 1.25125 | N45: =COUNTIF(N2:N42,0) -> 40
A46: Std Dev/Count- | B46: =_xlfn.STDEV.S(B2:B42) -> 6.7539973 | C46: =COUNTIF(C3:C43,"Male") -> 18 | D46: =_xlfn.STDEV.S(D2:D42) -> 21.869931 | E46: =_xlfn.STDEV.S(E2:E42) -> 9.046425 | F46: =_xlfn.STDEV.S(F2:F42) -> 9.2339054 | G46: =_xlfn.STDEV.S(G2:G42) -> 15.250609 | H46: =_xlfn.STDEV.S(H2:H42) -> 9.1501768 | I46: =_xlfn.STDEV.S(I2:I42) -> 9.1725103 | J46: =_xlfn.STDEV.S(J2:J42) -> 0.66243782 | K46: =_xlfn.STDEV.S(K2:K42) -> 0.22713587 | N46: =COUNTIF(N2:N42,1) -> 1
A47: Maximum/Total | B47: =MAX(B2:B42) -> 90.37 | C47: =SUM(C45:C46) -> 41 | D47: =MAX(D2:D42) -> 198 | E47: =MAX(E2:E42) -> 92 | F47: =MAX(F2:F42) -> 85.7143 | G47: =MAX(G2:G42) -> 64.6669 | H47: =MAX(H2:H42) -> 39.6659 | I47: =MAX(I2:I42) -> 40.10145 | J47: =MAX(J2:J42) -> 5.235 | K47: =MAX(K2:K42) -> 1.825 | N47: =SUM(N45:N46) -> 41
A48: Minimum/Pct | B48: =MIN(B2:B42) -> 65.64 | C48: =C45/(C45+C46)*100 -> 56.097561 | D48: =MIN(D2:D42) -> 100 | E48: =MIN(E2:E42) -> 49 | F48: =MIN(F2:F42) -> 40.7056 | G48: =MIN(G2:G42) -> 3.3709 | H48: =MIN(H2:H42) -> 2.0804 | I48: =MIN(I2:I42) -> 5.43205 | J48: =MIN(J2:J42) -> 2.215 | K48: =MIN(K2:K42) -> 0.845 | N48: =N46/N47*100 -> 2.4390244
A50: Categorical | K50: APOE e2,2 | L50: 0
K51: APOE e2,3/3,2 | L51: 7
K52: APOE e3,3 | L52: 33
K53: APOE e3,4/4,3 | L53: 1
K54: APOE e4,4 | L54: 0

Sheet Combined
A1: id | B1: age | C1: sex | D1: spb | E1: dbp | F1: HR (bpm) | G1: pwv lt_ica | H1: pwv rt_ica | I1: pwv_avg | J1: flow petrous L&R | K1: PI petrous L&R | L1: apoe_e1 | M1: apoe_e2 | N1: FmHx_dementia
A2: 'adrc00343_v2' | B2: 87.97 | C2: Male | D2: 146 | E2: 80 | F2: 63.5593 | G2: 22.7851 | H2: 24.1701 | I2: 23.4776 | J2: 3.29 | K2: 1.385 | L2: 3 | M2: 3 | N2: 0
A3: 'adrc00405_v2' | B3: 72.51 | C3: Female | D3: 150 | E3: 80 | F3: 92.8793 | G3: 42.6706 | H3: 61.8207 | I3: 52.24565 | J3: 2.455 | K3: 1.335 | L3: 3 | M3: 4 | N3: 1
A4: 'adrc00564' | B4: 69.89 | C4: Male | D4: 143 | E4: 78 | F4: 60.3622 | G4: 42.9005 | H4: 10.4241 | I4: 26.6623 | J4: 3.205 | K4: 1.27 | L4: 2 | M4: 3 | N4: 0
A5: 'adrc00609_v2' | B5: 73.79 | C5: Female | D5: 135 | E5: 74 | F5: 58.1395 | G5: 21.2414 | H5: 14.2388 | I5: 17.7401 | J5: 3.395 | K5: 1.435 | L5: 3 | M5: 4 | N5: 0
A6: 'adrc00739' | B6: 69.59 | C6: Male | D6: 115 | E6: 74 | F6: 55.2486 | G6: 23.5081 | H6: 12.072 | I6: 17.79005 | J6: 2.4 | K6: 1.25 | L6: 3 | M6: 4 | N6: 0
A7: 'adrc00750' | B7: 69.97 | C7: Female | D7: 131 | E7: 81 | F7: 56.4972 | G7: 24.6867 | H7: 28.1528 | I7: 26.41975 | J7: 3.085 | K7: 1.175 | L7: 4 | M7: 4 | N7: 1
A8: 'adrc00778' | B8: 71.55 | C8: Female | D8: 116 | E8: 74 | F8: 56.7108 | G8: 31.1677 | H8: 40.2925 | I8: 35.7301 | J8: 2.85 | K8: 1.415 | L8: 3 | M8: 4 | N8: 1
A9: 'adrc00791' | B9: 83.97 | C9: Female | D9: 158 | E9: 71 | F9: 66.0793 | G9: 33.9961 | H9: 14.5291 | I9: 24.2626 | J9: 4.43 | K9: 1.815 | N9: 1
A10: 'adrc00811' | B10: 60.7 | C10: Female | D10: 106 | E10: 69 | F10: 46.0829 | G10: 20.7964 | H10: 20.4119 | I10: 20.60415 | J10: 3.615 | K10: 0.935 | L10: 3 | M10: 3 | N10: 0
A11: 'adrc00820' | B11: 75.32 | C11: Female | D11: 148 | E11: 76 | F11: 71.2589 | H11: 25.7992 | I11: 25.7992 | J11: 3.13 | K11: 1.01 | L11: 3 | M11: 4 | N11: 1
A12: 'adrc00860' | B12: 79.81 | C12: Male | D12: 163 | E12: 75 | F12: 58.8235 | G12: 47.8929 | H12: 27.5652 | I12: 37.72905 | J12: 3.08 | K12: 1.54 | L12: 3 | M12: 3 | N12: 0
A13: 'adrc00863' | B13: 78.37 | C13: Female | D13: 125 | E13: 84 | F13: 58.9391 | G13: 40.6728 | H13: 18.9284 | I13: 29.8006 | J13: 2.49 | K13: 1.28 | N13: 0
A14: 'adrc00893' | B14: 66.95 | C14: Male | D14: 132 | E14: 81 | F14: 61.6016 | G14: 53.2659 | H14: 39.7415 | I14: 46.5037 | J14: 2.11 | K14: 1.43 | L14: 3 | M14: 3 | N14: 1
A15: 'adrc00894' | B15: 68.4 | C15: Female | D15: 128 | E15: 83 | F15: 44.7094 | G15: 22.1171 | H15: 13.7371 | I15: 17.9271 | J15: 4.425 | K15: 0.915 | N15: 0
A16: 'adrc00903' | B16: 87.92 | C16: Female | D16: 110 | E16: 68 | F16: 78.7402 | G16: 15.723 | H16: 21.2495 | I16: 18.48625 | J16: 2.67 | K16: 1.51 | L16: 2 | M16: 3 | N16: 0
A17: 'adrc00919' | B17: 77.85 | C17: Male | D17: 134 | E17: 79 | F17: 55.0459 | G17: 33.9934 | H17: 40.3648 | I17: 37.1791 | J17: 2.81 | K17: 1.185 | N17: 0
A18: 'adrc00920' | B18: 56.52 | C18: Female | D18: 110 | E18: 68 | F18: 55.2486 | G18: 17.0583 | H18: 40.9106 | I18: 28.98445 | J18: 5.2 | K18: 0.68 | N18: 0
A19: 'adrc00934' | B19: 67.95 | C19: Female | D19: 117 | E19: 71 | F19: 53.9568 | G19: 27.2989 | H19: 33.9629 | I19: 30.6309 | J19: 3.965 | K19: 1.065 | N19: 1
A20: 'adrc00939' | B20: 88.55 | C20: Female | D20: 153 | E20: 72 | F20: 55.9701 | G20: 17.7166 | H20: 29.0608 | I20: 23.3887 | J20: 2.285 | K20: 1.955 | N20: 0
A21: 'adrc00964' | B21: 60.63 | C21: Male | D21: 95 | E21: 61 | F21: 50 | G21: 18.1421 | H21: 16.5245 | I21: 17.3333 | J21: 2.89 | K21: 1.26 | N21: 0
A22: 'pdt00258_v3' | B22: 69.3 | C22: Female | D22: 107 | E22: 67 | F22: 60 | G22: 3.4546 | H22: 38.3758 | I22: 20.9152 | J22: 3.935 | K22: 1.025 | L22: 3 | M22: 3 | N22: 0
A23: 'pdt00218_v3' | B23: 70.35 | C23: Female | D23: 140 | E23: 80 | F23: 58.9391 | G23: 10.974 | H23: 7.8829 | I23: 9.42845 | J23: 3.145 | K23: 1.385 | L23: 3 | M23: 3 | N23: 0
A24: 'pdt00202_v3' | B24: 66.91 | C24: Male | D24: 142 | E24: 87 | F24: 74.4417 | G24: 15.6376 | H24: 3.7263 | I24: 9.68195 | J24: 3.9 | K24: 1.22 | L24: 3 | M24: 3 | N24: 0
A25: 'pdt00092_v3' | B25: 71.31 | C25: Male | D25: 162 | E25: 74 | F25: 54.5455 | G25: 36.79 | H25: 17.3074 | I25: 27.0487 | J25: 2.215 | K25: 1.64 | L25: 3 | M25: 3 | N25: 0
A26: 'pdt00056_v3' | B26: 77.41 | C26: Female | D26: 136 | E26: 82 | F26: 67.2646 | G26: 6.0812 | H26: 17.605 | I26: 11.8431 | J26: 3.345 | K26: 1.23 | L26: 3 | M26: 3 | N26: 0
A27: 'pdt00049_v3' | B27: 73.74 | C27: Male | D27: 134 | E27: 74 | F27: 55.2486 | G27: 4.5718 | H27: 11.3051 | I27: 7.93845 | J27: 3.96 | K27: 1.385 | L27: 3 | M27: 3 | N27: 0
A28: 'pdt00045_v3' | B28: 69.86 | C28: Female | D28: 110 | E28: 68 | F28: 52.1739 | G28: 9.9058 | H28: 9.5239 | I28: 9.71485 | J28: 3.72 | K28: 1.56 | L28: 3 | M28: 3 | N28: 0
A29: 'pdt00035_v3' | B29: 70.31 | C29: Male | D29: 136 | E29: 80 | F29: 64.7948 | G29: 7.2277 | H29: 12.5649 | I29: 9.8963 | J29: 3.87 | K29: 1.145 | L29: 3 | M29: 3 | N29: 0
A30: 'pdt00034_v3' | B30: 73.48 | C30: Female | D30: 156 | E30: 74 | F30: 52.6316 | G30: 19.6663 | H30: 9.2447 | I30: 14.4555 | J30: 3.38 | K30: 1.33 | L30: 3 | M30: 3 | N30: 0
A31: 'adrc00808_v2' | B31: 65.68 | C31: Female | D31: 121 | E31: 74 | F31: 55.4529 | G31: 15.3962 | H31: 7.3219 | I31: 11.35905 | J31: 3.97 | K31: 1.175 | L31: 3 | M31: 4 | N31: 0
A32: 'adrc00788' | B32: 66.59 | C32: Female | D32: 142 | E32: 85 | F32: 71.9424 | G32: 13.7517 | H32: 12.2956 | I32: 13.02365 | J32: 3.77 | K32: 0.925 | L32: 3 | M32: 3 | N32: 1
A33: 'adrc00773' | B33: 68.97 | C33: Male | D33: 113 | E33: 79 | F33: 76.7263 | G33: 6.3975 | H33: 11.9538 | I33: 9.17565 | J33: 3.74 | K33: 0.845 | L33: 2 | M33: 3 | N33: 0
... A60: 'adrc00694_v3' | B60: 69.39 | C60: Female | D60: 113 | E60: 76 | F60: 63.1579 | G60: 3.3709 | H60: 7.8114 | I60: 5.59115 | J60: 3.55 | K60: 0.87 | L60: 3 | M60: 3 | N60: 0
A61: 'adrc00767_v2' | B61: 68.16 | C61: Female | D61: 154 | E61: 90 | F61: 63.9659 | G61: 7.9788 | H61: 8.0018 | I61: 7.9903 | J61: 3.295 | L61: 3 | M61: 3 | N61: 0
A62: 'adrc00855_v2' | B62: 77.94 | C62: Female | D62: 169 | E62: 77 | F62: 63.4249 | G62: 31.0069 | H62: 24.3593 | I62: 27.6831 | J62: 3.305 | K62: 1.53 | L62: 2 | M62: 3 | N62: 0
A64: ="# SUBJECTS= " & COUNTA(A2:A62) -> # SUBJECTS= 61 | C64: Female/Male
A65: Mean | B65: =AVERAGE(B2:B62) -> 73.490492 | C65: =COUNTIF(C2:C62,"Female") -> 36 | D65: =AVERAGE(D2:D62) -> 131.85246 | E65: =AVERAGE(E2:E62) -> 76.754098 | F65: =AVERAGE(F2:F62) -> 61.062616 | G65: =AVERAGE(G2:G62) -> 23.461393 | H65: =AVERAGE(H2:H62) -> 18.391482 | I65: =AVERAGE(I2:I62) -> 20.9456 | J65: =AVERAGE(J2:J62) -> 3.3693443 | K65: =AVERAGE(K2:K62) -> 1.2649167 | N65: =COUNTIF(N2:N62,0) -> 53
A66: Std Dev | B66: =_xlfn.STDEV.S(B2:B62) -> 7.557621 | C66: =COUNTIF(C2:C62,"Male") -> 25 | D66: =_xlfn.STDEV.S(D2:D62) -> 20.806118 | E66: =_xlfn.STDEV.S(E2:E62) -> 8.2029583 | F66: =_xlfn.STDEV.S(F2:F62) -> 9.7766696 | G66: =_xlfn.STDEV.S(G2:G62) -> 14.619917 | H66: =_xlfn.STDEV.S(H2:H62) -> 11.993709 | I66: =_xlfn.STDEV.S(I2:I62) -> 10.51479 | J66: =_xlfn.STDEV.S(J2:J62) -> 0.71582148 | K66: =_xlfn.STDEV.S(K2:K62) -> 0.25128229 | L66: =COUNTIF(L2:L62,2) -> 9 | M66: =COUNTIF(M2:M62,2) -> 0 | N66: =COUNTIF(N2:N62,1) -> 8
A67: Maximum | B67: =MAX(B2:B62) -> 90.37 | C67: =SUM(C65:C66) -> 61 | D67: =MAX(D2:D62) -> 198 | E67: =MAX(E2:E62) -> 92 | F67: =MAX(F2:F62) -> 92.8793 | G67: =MAX(G2:G62) -> 64.6669 | H67: =MAX(H2:H62) -> 61.8207 | I67: =MAX(I2:I62) -> 52.24565 | J67: =MAX(J2:J62) -> 5.235 | K67: =MAX(K2:K62) -> 1.955 | L67: =COUNTIF(L2:L62,3) -> 43 | M67: =COUNTIF(M2:M62,3) -> 46 | N67: =SUM(N65:N66) -> 61
...

Sheet Stats
B1: Age | C1: Sex | D1: spb | E1: dbp | F1: HR (bpm) | G1: pwv lt_ica | H1: pwv rt_ica | I1: pwv_avg | J1: flow petrous L&R | K1: PI petrous L&R | L1: apoe4_carrier | M1: FmHx
A2: F-test | B2: =_xlfn.F.TEST(AD!B2:B21,CN!B2:B42) -> 0.10127236 | D2: =_xlfn.F.TEST(AD!D2:D21,CN!D2:D42) -> 0.5047831 | E2: =_xlfn.F.TEST(AD!E2:E21,CN!E2:E42) -> 0.050170537 | F2: =_xlfn.F.TEST(AD!F2:F21,CN!F2:F42) -> 0.35029615 | G2: =_xlfn.F.TEST(AD!G2:G21,CN!G2:G42) -> 0.18574965 | H2: =_xlfn.F.TEST(AD!H2:H21,CN!H2:H42) -> 0.05919102 | I2: =_xlfn.F.TEST(AD!I2:I21,CN!I2:I42) -> 0.71265178 | J2: =_xlfn.F.TEST(AD!J2:J21,CN!J2:J42) -> 0.30362836 | K2: =_xlfn.F.TEST(AD!K2:K21,CN!K2:K42) -> 0.14784852
A3: T-test | B3: =_xlfn.T.TEST(AD!B2:B21,CN!B2:B42,2,3) -> 0.95923218 | D3: =_xlfn.T.TEST(AD!D2:D21,CN!D2:D42,2,2) -> 0.77525355 | E3: =_xlfn.T.TEST(AD!E2:E21,CN!E2:E42,2,2) -> 0.23331896 | F3: =_xlfn.T.TEST(AD!F2:F21,CN!F2:F42,2,2) -> 0.55494579 | G3: =_xlfn.T.TEST(AD!G2:G21,CN!G2:G42,2,2) -> 0.032492367 | H3: =_xlfn.T.TEST(AD!H2:H21,CN!H2:H42,2,2) -> 6.6976965e-05 | I3: =_xlfn.T.TEST(AD!I2:I21,CN!I2:I42,2,2) -> 0.00014228499 | J3: =_xlfn.T.TEST(AD!J2:J21,CN!J2:J42,2,2) -> 0.17133362 | K3: =_xlfn.T.TEST(AD!K2:K21,CN!K2:K42,2,2) -> 0.55581762
A4: Fisher Exact Test | C4: {=[1]!FISHERTEST(B5:C6)} -> 0.58369414 | L4: {=[1]!FISHERTEST(L5:M6)} -> 0.00025090974 | M4: {=[1]!FISHERTEST(L9:M10)} -> 0.0011220656
B5: 13 | C5: 23 | L5: 6 | M5: 40
B6: 7 | C6: 19 | L6: 6 | M6: 1
C7: sex | M7: Carrier
L9: 40 | M9: 13
L10: 1 | M10: 7
M11: FmHx
